Error! When make dir /Users/taohuadao/Downloads/MtProject/outputstrain_2022-10-14-12-59-09/, the path status is:True
Reading training data...
Traceback (most recent call last):
  File "/Users/taohuadao/opt/anaconda3/envs/daily/lib/python3.8/site-packages/urllib3/connectionpool.py", line 703, in urlopen
    httplib_response = self._make_request(
  File "/Users/taohuadao/opt/anaconda3/envs/daily/lib/python3.8/site-packages/urllib3/connectionpool.py", line 386, in _make_request
    self._validate_conn(conn)
  File "/Users/taohuadao/opt/anaconda3/envs/daily/lib/python3.8/site-packages/urllib3/connectionpool.py", line 1040, in _validate_conn
    conn.connect()
  File "/Users/taohuadao/opt/anaconda3/envs/daily/lib/python3.8/site-packages/urllib3/connection.py", line 414, in connect
    self.sock = ssl_wrap_socket(
  File "/Users/taohuadao/opt/anaconda3/envs/daily/lib/python3.8/site-packages/urllib3/util/ssl_.py", line 449, in ssl_wrap_socket
    ssl_sock = _ssl_wrap_socket_impl(
  File "/Users/taohuadao/opt/anaconda3/envs/daily/lib/python3.8/site-packages/urllib3/util/ssl_.py", line 493, in _ssl_wrap_socket_impl
    return ssl_context.wrap_socket(sock, server_hostname=server_hostname)
  File "/Users/taohuadao/opt/anaconda3/envs/daily/lib/python3.8/ssl.py", line 500, in wrap_socket
    return self.sslsocket_class._create(
  File "/Users/taohuadao/opt/anaconda3/envs/daily/lib/python3.8/ssl.py", line 1040, in _create
    self.do_handshake()
  File "/Users/taohuadao/opt/anaconda3/envs/daily/lib/python3.8/ssl.py", line 1309, in do_handshake
    self._sslobj.do_handshake()
ssl.SSLCertVerificationError: [SSL: CERTIFICATE_VERIFY_FAILED] certificate verify failed: self-signed certificate in certificate chain (_ssl.c:1131)

During handling of the above exception, another exception occurred:

Traceback (most recent call last):
  File "/Users/taohuadao/opt/anaconda3/envs/daily/lib/python3.8/site-packages/requests/adapters.py", line 440, in send
    resp = conn.urlopen(
  File "/Users/taohuadao/opt/anaconda3/envs/daily/lib/python3.8/site-packages/urllib3/connectionpool.py", line 785, in urlopen
    retries = retries.increment(
  File "/Users/taohuadao/opt/anaconda3/envs/daily/lib/python3.8/site-packages/urllib3/util/retry.py", line 592, in increment
    raise MaxRetryError(_pool, url, error or ResponseError(cause))
urllib3.exceptions.MaxRetryError: HTTPSConnectionPool(host='huggingface.co', port=443): Max retries exceeded with url: /facebook/mbart-large-50/resolve/main/sentencepiece.bpe.model (Caused by SSLError(SSLCertVerificationError(1, '[SSL: CERTIFICATE_VERIFY_FAILED] certificate verify failed: self-signed certificate in certificate chain (_ssl.c:1131)')))

During handling of the above exception, another exception occurred:

Traceback (most recent call last):
  File "run.py", line 172, in <module>
    train_set = ParallelCorpus(train_data, cfg)
  File "run.py", line 33, in __init__
    self.tokenizer = MBart50TokenizerFast.from_pretrained(cfg['model_name'])
  File "/Users/taohuadao/opt/anaconda3/envs/daily/lib/python3.8/site-packages/transformers/tokenization_utils_base.py", line 1723, in from_pretrained
    resolved_vocab_files[file_id] = cached_path(
  File "/Users/taohuadao/opt/anaconda3/envs/daily/lib/python3.8/site-packages/transformers/utils/hub.py", line 282, in cached_path
    output_path = get_from_cache(
  File "/Users/taohuadao/opt/anaconda3/envs/daily/lib/python3.8/site-packages/transformers/utils/hub.py", line 485, in get_from_cache
    r = requests.head(url, headers=headers, allow_redirects=False, proxies=proxies, timeout=etag_timeout)
  File "/Users/taohuadao/opt/anaconda3/envs/daily/lib/python3.8/site-packages/requests/api.py", line 102, in head
    return request('head', url, **kwargs)
  File "/Users/taohuadao/opt/anaconda3/envs/daily/lib/python3.8/site-packages/requests/api.py", line 61, in request
    return session.request(method=method, url=url, **kwargs)
  File "/Users/taohuadao/opt/anaconda3/envs/daily/lib/python3.8/site-packages/requests/sessions.py", line 529, in request
    resp = self.send(prep, **send_kwargs)
  File "/Users/taohuadao/opt/anaconda3/envs/daily/lib/python3.8/site-packages/requests/sessions.py", line 645, in send
    r = adapter.send(request, **kwargs)
  File "/Users/taohuadao/opt/anaconda3/envs/daily/lib/python3.8/site-packages/requests/adapters.py", line 517, in send
    raise SSLError(e, request=request)
requests.exceptions.SSLError: HTTPSConnectionPool(host='huggingface.co', port=443): Max retries exceeded with url: /facebook/mbart-large-50/resolve/main/sentencepiece.bpe.model (Caused by SSLError(SSLCertVerificationError(1, '[SSL: CERTIFICATE_VERIFY_FAILED] certificate verify failed: self-signed certificate in certificate chain (_ssl.c:1131)')))
